[32mINFO    [0m pytestify.client.api_client:api_client.py:30 Initialized APIClient with base URL: http://localhost:8080
[35mDEBUG   [0m pytestify.client.api_client:api_client.py:50 Created URL: http://localhost:8080/posts
[32mINFO    [0m pytestify.client.api_client:api_client.py:83 Performing POST request to http://localhost:8080/posts with data: None and json: {'title': 'foo', 'body': 'bar'}
[35mDEBUG   [0m urllib3.connectionpool:connectionpool.py:243 Starting new HTTP connection (1): localhost:8080
[35mDEBUG   [0m urllib3.connectionpool:connectionpool.py:546 http://localhost:8080 "POST /posts HTTP/11" 404 None
[33mWARNING [0m root:utils.py:15 Request failed: 404 Client Error: Not Found for url: http://localhost:8080/posts. Retrying... (1/3)
[35mDEBUG   [0m urllib3.connectionpool:connectionpool.py:546 http://localhost:8080 "POST /posts HTTP/11" 404 None
[33mWARNING [0m root:utils.py:15 Request failed: 404 Client Error: Not Found for url: http://localhost:8080/posts. Retrying... (2/3)
[35mDEBUG   [0m urllib3.connectionpool:connectionpool.py:546 http://localhost:8080 "POST /posts HTTP/11" 404 None
[33mWARNING [0m root:utils.py:15 Request failed: 404 Client Error: Not Found for url: http://localhost:8080/posts. Retrying... (3/3)
[31mCRITICAL[0m root:utils.py:23 Request failed after 3 attempts.
[1m[31mERROR   [0m pytestify.client.api_client:api_client.py:88 POST request to http://localhost:8080/posts failed and returned None
[32mINFO    [0m pytestify.client.api_client:api_client.py:141 Closed APIClient session